[ 2025-08-09 00:31:16,010 ] 97 werkzeug - INFO - [31m[1mWARNING: This is a development server. Do not use it in a production deployment. Use a production WSGI server instead.[0m
 * Running on all addresses (0.0.0.0)
 * Running on http://127.0.0.1:5000
 * Running on http://192.168.1.5:5000
[ 2025-08-09 00:31:16,011 ] 97 werkzeug - INFO - [33mPress CTRL+C to quit[0m
[ 2025-08-09 00:31:23,640 ] 97 werkzeug - INFO - 127.0.0.1 - - [09/Aug/2025 00:31:23] "GET / HTTP/1.1" 200 -
[ 2025-08-09 00:31:26,340 ] 838 app - ERROR - Exception on /predictdata [GET]
Traceback (most recent call last):
  File "C:\Users\LENOVO\anaconda3\Lib\site-packages\flask\app.py", line 1473, in wsgi_app
    response = self.full_dispatch_request()
               ^^^^^^^^^^^^^^^^^^^^^^^^^^^^
  File "C:\Users\LENOVO\anaconda3\Lib\site-packages\flask\app.py", line 882, in full_dispatch_request
    rv = self.handle_user_exception(e)
         ^^^^^^^^^^^^^^^^^^^^^^^^^^^^^
  File "C:\Users\LENOVO\anaconda3\Lib\site-packages\flask\app.py", line 880, in full_dispatch_request
    rv = self.dispatch_request()
         ^^^^^^^^^^^^^^^^^^^^^^^
  File "C:\Users\LENOVO\anaconda3\Lib\site-packages\flask\app.py", line 865, in dispatch_request
    return self.ensure_sync(self.view_functions[rule.endpoint])(**view_args)  # type: ignore[no-any-return]
           ^^^^^^^^^^^^^^^^^^^^^^^^^^^^^^^^^^^^^^^^^^^^^^^^^^^^^^^^^^^^^^^^^
  File "D:\DS-Project\Student-Performance-Indicator\app.py", line 23, in predict_datapoint
    results=predicted_value,
            ^^^^^^^^^^^^^^^
NameError: name 'predicted_value' is not defined
[ 2025-08-09 00:31:26,361 ] 97 werkzeug - INFO - 127.0.0.1 - - [09/Aug/2025 00:31:26] "[35m[1mGET /predictdata HTTP/1.1[0m" 500 -
[ 2025-08-09 00:31:27,923 ] 838 app - ERROR - Exception on /predictdata [GET]
Traceback (most recent call last):
  File "C:\Users\LENOVO\anaconda3\Lib\site-packages\flask\app.py", line 1473, in wsgi_app
    response = self.full_dispatch_request()
               ^^^^^^^^^^^^^^^^^^^^^^^^^^^^
  File "C:\Users\LENOVO\anaconda3\Lib\site-packages\flask\app.py", line 882, in full_dispatch_request
    rv = self.handle_user_exception(e)
         ^^^^^^^^^^^^^^^^^^^^^^^^^^^^^
  File "C:\Users\LENOVO\anaconda3\Lib\site-packages\flask\app.py", line 880, in full_dispatch_request
    rv = self.dispatch_request()
         ^^^^^^^^^^^^^^^^^^^^^^^
  File "C:\Users\LENOVO\anaconda3\Lib\site-packages\flask\app.py", line 865, in dispatch_request
    return self.ensure_sync(self.view_functions[rule.endpoint])(**view_args)  # type: ignore[no-any-return]
           ^^^^^^^^^^^^^^^^^^^^^^^^^^^^^^^^^^^^^^^^^^^^^^^^^^^^^^^^^^^^^^^^^
  File "D:\DS-Project\Student-Performance-Indicator\app.py", line 23, in predict_datapoint
    results=predicted_value,
            ^^^^^^^^^^^^^^^
NameError: name 'predicted_value' is not defined
[ 2025-08-09 00:31:27,947 ] 97 werkzeug - INFO - 127.0.0.1 - - [09/Aug/2025 00:31:27] "[35m[1mGET /predictdata HTTP/1.1[0m" 500 -
[ 2025-08-09 00:32:15,887 ] 838 app - ERROR - Exception on /predictdata [GET]
Traceback (most recent call last):
  File "C:\Users\LENOVO\anaconda3\Lib\site-packages\flask\app.py", line 1473, in wsgi_app
    response = self.full_dispatch_request()
               ^^^^^^^^^^^^^^^^^^^^^^^^^^^^
  File "C:\Users\LENOVO\anaconda3\Lib\site-packages\flask\app.py", line 882, in full_dispatch_request
    rv = self.handle_user_exception(e)
         ^^^^^^^^^^^^^^^^^^^^^^^^^^^^^
  File "C:\Users\LENOVO\anaconda3\Lib\site-packages\flask\app.py", line 880, in full_dispatch_request
    rv = self.dispatch_request()
         ^^^^^^^^^^^^^^^^^^^^^^^
  File "C:\Users\LENOVO\anaconda3\Lib\site-packages\flask\app.py", line 865, in dispatch_request
    return self.ensure_sync(self.view_functions[rule.endpoint])(**view_args)  # type: ignore[no-any-return]
           ^^^^^^^^^^^^^^^^^^^^^^^^^^^^^^^^^^^^^^^^^^^^^^^^^^^^^^^^^^^^^^^^^
  File "D:\DS-Project\Student-Performance-Indicator\app.py", line 23, in predict_datapoint
    results=predicted_value,
            ^^^^^^^^^^^^^^^
NameError: name 'predicted_value' is not defined
[ 2025-08-09 00:32:15,909 ] 97 werkzeug - INFO - 127.0.0.1 - - [09/Aug/2025 00:32:15] "[35m[1mGET /predictdata HTTP/1.1[0m" 500 -
[ 2025-08-09 00:32:20,285 ] 838 app - ERROR - Exception on /predictdata [GET]
Traceback (most recent call last):
  File "C:\Users\LENOVO\anaconda3\Lib\site-packages\flask\app.py", line 1473, in wsgi_app
    response = self.full_dispatch_request()
               ^^^^^^^^^^^^^^^^^^^^^^^^^^^^
  File "C:\Users\LENOVO\anaconda3\Lib\site-packages\flask\app.py", line 882, in full_dispatch_request
    rv = self.handle_user_exception(e)
         ^^^^^^^^^^^^^^^^^^^^^^^^^^^^^
  File "C:\Users\LENOVO\anaconda3\Lib\site-packages\flask\app.py", line 880, in full_dispatch_request
    rv = self.dispatch_request()
         ^^^^^^^^^^^^^^^^^^^^^^^
  File "C:\Users\LENOVO\anaconda3\Lib\site-packages\flask\app.py", line 865, in dispatch_request
    return self.ensure_sync(self.view_functions[rule.endpoint])(**view_args)  # type: ignore[no-any-return]
           ^^^^^^^^^^^^^^^^^^^^^^^^^^^^^^^^^^^^^^^^^^^^^^^^^^^^^^^^^^^^^^^^^
  File "D:\DS-Project\Student-Performance-Indicator\app.py", line 23, in predict_datapoint
    results=predicted_value,
            ^^^^^^^^^^^^^^^
NameError: name 'predicted_value' is not defined
[ 2025-08-09 00:32:20,314 ] 97 werkzeug - INFO - 127.0.0.1 - - [09/Aug/2025 00:32:20] "[35m[1mGET /predictdata HTTP/1.1[0m" 500 -
[ 2025-08-09 00:32:48,397 ] 838 app - ERROR - Exception on /predictdata [GET]
Traceback (most recent call last):
  File "C:\Users\LENOVO\anaconda3\Lib\site-packages\flask\app.py", line 1473, in wsgi_app
    response = self.full_dispatch_request()
               ^^^^^^^^^^^^^^^^^^^^^^^^^^^^
  File "C:\Users\LENOVO\anaconda3\Lib\site-packages\flask\app.py", line 882, in full_dispatch_request
    rv = self.handle_user_exception(e)
         ^^^^^^^^^^^^^^^^^^^^^^^^^^^^^
  File "C:\Users\LENOVO\anaconda3\Lib\site-packages\flask\app.py", line 880, in full_dispatch_request
    rv = self.dispatch_request()
         ^^^^^^^^^^^^^^^^^^^^^^^
  File "C:\Users\LENOVO\anaconda3\Lib\site-packages\flask\app.py", line 865, in dispatch_request
    return self.ensure_sync(self.view_functions[rule.endpoint])(**view_args)  # type: ignore[no-any-return]
           ^^^^^^^^^^^^^^^^^^^^^^^^^^^^^^^^^^^^^^^^^^^^^^^^^^^^^^^^^^^^^^^^^
  File "D:\DS-Project\Student-Performance-Indicator\app.py", line 23, in predict_datapoint
    data=CustomData(
            ^^^^^^^^^
NameError: name 'predicted_value' is not defined
[ 2025-08-09 00:32:48,418 ] 97 werkzeug - INFO - 127.0.0.1 - - [09/Aug/2025 00:32:48] "[35m[1mGET /predictdata HTTP/1.1[0m" 500 -
